Workbook

Sheet GiaDinh
A1: GIẢ ĐỊNH — SAMESIES, 60 ngày (3/11/2026 → 2/1/2027; tiền khởi động 19/10–2/11 chi 0 ₫)
A2: XANH = ô nhập liệu (sửa được) · ĐEN = công thức · XANH LÁ = lấy từ sheet khác · nền VÀNG = giả định then chốt. Cột J ghi nguồn.
A4: Vốn ban đầu (₫) | B4: 10000000 | J4: Đề bài của chủ dự án
A5: Mục tiêu lợi nhuận ròng (₫) | B5: 30000000 | J5: KPI bắt buộc
A6: Ngày bắt đầu (ngày lương về) | B6: 46329 | J6: Ngày 1 = 3/11/2026; 19/10–2/11 là giai đoạn tiền khởi động chi 0 ₫
A7: Ngày chốt sổ | B7: 46389 | J7: Sau 60 ngày
A8: Số ngày kinh doanh | B8: =B7-B6 -> 60 | J8: Bằng ngày chốt trừ ngày bắt đầu
A10: KÊNH BÁN
A11: Kênh | B11: Hoa hồng sàn | C11: Phí giao dịch | D11: Thuế sàn khấu trừ | E11: Tỷ trọng đơn | F11: Phí cố định/đơn (₫) | G11: Tổng % phí | J11: Nguồn
A12: TikTok Shop | B12: 0.15 | C12: 0.06 | D12: 0.015 | E12: 0.45 | F12: 3000 | G12: =B12+C12+D12 -> 0.225 | J12: PDF biểu phí TikTok Seller University hiệu lực 03/07/2026: hoodie/áo thun/bộ đồ cặp đôi 15%; phí giao dịch 6% từ 09/05/2026 (shop mới có thể được 0% trong 60 ngày, chưa xác nhận đợt Q4); xử lý đơn 3.000đ; thuế 1,5% theo NĐ 117/2025
A13: Shopee | B13: 0.165 | C13: 0.06 | D13: 0.015 | E13: 0.1 | F13: 5700 | G13: =B13+C13+D13 -> 0.24 | J13: Phí cố định thời trang 14,5–16,5% từ 23/05/2026; phí giao dịch 6% từ 01/05/2026; hạ tầng 3.000đ + PiShip 2.700đ; shop mới miễn phí cố định 30 ngày
A14: Trực tiếp: Zalo / Instagram / Facebook (COD qua SPX, GHN) | B14: 0 | C14: 0 | D14: 0 | E14: 0.45 | F14: 0 | G14: =B14+C14+D14 -> 0 | J14: Không phí sàn; COD miễn phí (SPX ≤20tr, GHN); doanh thu ≤1 tỷ/năm miễn GTGT & TNCN theo NĐ 141/2026, tự kê khai mẫu 01/CNKD
A15: Bình quân gia quyền theo tỷ trọng đơn | B15: =SUMPRODUCT(B12:B14,$E$12:$E$14) -> 0.084 | C15: =SUMPRODUCT(C12:C14,$E$12:$E$14) -> 0.033 | D15: =SUMPRODUCT(D12:D14,$E$12:$E$14) -> 0.00825 | E15: =SUM(E12:E14) -> 1 | F15: =SUMPRODUCT(F12:F14,$E$12:$E$14) -> 1920 | G15: =SUMPRODUCT(G12:G14,$E$12:$E$14) -> 0.12525 | H15: =IF(ABS(E15-1)<0.001,"OK","SAI: tỷ trọng ≠ 100%") -> OK
A17: CHI PHÍ TRÊN MỖI ĐƠN
A18: Ship shop chịu bình quân/đơn (₫) | B18: 16000 | J18: Freeship mọi kênh (chính sách). TikTok: Xtra Shipping Voucher 5,5% trần 30k ≈ 20k/đơn ×45%; Shopee: sàn tự tài trợ freeship từ 01/04/2025 ≈ 0 ×10%; trực tiếp: SPX 14–15k (Sapo 10/2026) ×45% → bình quân ≈ 16k
A19: Bao bì/đơn (₫) | B19: 5000 | J19: Túi kraft in logo 2.300 (HOSO) + sticker 1.300 (Azoka) + thiệp 1.000 (In Thủ Đô) + túi niêm phong 400
A20: Tỷ lệ hoàn/bom hàng | B20: 0.1 | J20: Quần áo 5–10% (Sapo); COD 15% dịp sale (Tuổi Trẻ); có xác nhận đơn qua chat → 10%
A21: Lỗ mỗi đơn hoàn (₫) | B21: 40000 | J21: Ship chiều đi 15–19k + bao bì 5k + hoa hồng/phí giao dịch TikTok vẫn thu trên đơn hoàn từ 01/04/2026
A22: Quảng cáo + affiliate/đơn (CAC, ₫) | B22: 30000 | J22: TikTok Ads CPM 25–50k, CPC 3–5k; affiliate 10–15% trên đơn creator; bình quân mọi đơn ≈ 8% doanh thu, dưới trần 10% của Nguyễn Phúc Long
A23: Độ trễ tiền sàn trả về (kỳ) | B23: 1 | J23: TikTok Standard 8 ngày với shop mới; COD SPX/GHN đối soát 2–4 ngày
A24: Tỷ lệ doanh thu nhận ngay trong kỳ (cọc) | B24: 0.25 | J24: Cọc 50% với đơn cá nhân hoá kênh trực tiếp (≈45% đơn) → ≈25% doanh thu về ngay
A26: SẢN PHẨM (giá theo BỘ/ĐƠN)
A27: Sản phẩm | B27: Giá niêm yết/bộ | C27: Giảm giá TB | D27: Giá bán thực | E27: Giá vốn hàng/bộ | F27: In/thêu/khắc/bộ | G27: Nhãn+hộp/bộ | H27: Tổng giá vốn | I27: Tỷ trọng đơn | J27: Nguồn giá vốn
A28: Áo nỉ Samesies — set 2 áo nỉ bông, in/thêu chữ cái + ngày kỷ niệm | B28: 499000 | C28: 0.08 | D28: =B28*(1-C28) -> 459080 | E28: 156000 | F28: 50000 | G28: 6000 | H28: =E28+F28+G28 -> 212000 | I28: 0.3 | J28: Nỉ bông trơn 65–87k/áo: Phương Yến HCM 75–87k (MOQ 1–3), Gấu Xám HN 65–69k (MOQ 3), THIDU 68–75k → 78k ×2; in decal nhỏ 15–23k (ThunViet) hoặc thêu ≈25k/áo (CẦN BÁO GIÁ) ×2; tag + túi 6k
A29: Áo thun Samesies — set 2 áo cotton 100%, in/thêu chữ cái + ngày | B29: 349000 | C29: 0.08 | D29: =B29*(1-C29) -> 321080 | E29: 100000 | F29: 50000 | G29: 6000 | H29: =E29+F29+G29 -> 156000 | I29: 0.25 | J29: Cotton 100%: AKUBA HCM 35–45k, Hà Đinh HN 55–65k → 50k ×2; in/thêu 25k ×2; tag + túi 6k
A30: Vòng Samesies — cặp vòng titan/inox khắc tên + hộp + thiệp | B30: 149000 | C30: 0 | D30: =B30*(1-C30) -> 149000 | E30: 17000 | F30: 20000 | G30: 8000 | H30: =E30+F30+G30 -> 45000 | I30: 0.25 | J30: Vòng tay cặp 15–17k (thitruongsi 10/2026); khắc laser ≈10k/chiếc (CẦN BÁO GIÁ); hộp lắp ráp 3,5k + thiệp 1k + túi 2,3k + sticker 1,3k
A31: Hộp Quà Kỷ Niệm Samesies — áo nỉ + vòng + thiệp viết tay + hộp quà | B31: 599000 | C31: 0.05 | D31: =B31*(1-C31) -> 569050 | E31: 173000 | F31: 70000 | G31: 22000 | H31: =E31+F31+G31 -> 265000 | I31: 0.2 | J31: Bằng áo nỉ (156k + 50k) + vòng (17k + 20k) + hộp quà Noel 16k + thiệp + túi 6k (Khánh Băng, thitruongsi)
A32: Đơn hàng bình quân (gia quyền theo tỷ trọng) | D32: =SUMPRODUCT(D28:D31,$I$28:$I$31) -> 369054 | H32: =SUMPRODUCT(H28:H31,$I$28:$I$31) -> 166850 | I32: =SUM(I28:I31) -> 1 | J32: =IF(ABS(I32-1)<0.001,"Tỷ trọng = 100%: OK","SAI: tỷ trọng ≠ 100%") -> Tỷ trọng = 100%: OK

Sheet DonVi
A1: KINH TẾ ĐƠN VỊ — lợi nhuận ròng trên 1 đơn, theo sản phẩm và đơn bình quân
A2: Mọi ô là công thức lấy từ GiaDinh; phí sàn dùng mức bình quân gia quyền theo tỷ trọng kênh.
A4: Khoản | B4: Áo nỉ Samesies | C4: Áo thun Samesies | D4: Vòng Samesies | E4: Hộp Quà Kỷ Niệm Samesies | F4: Đơn bình quân
A5: Giá bán thực (khách trả) | B5: =GiaDinh!D28 -> 459080 | C5: =GiaDinh!D29 -> 321080 | D5: =GiaDinh!D30 -> 149000 | E5: =GiaDinh!D31 -> 569050 | F5: =GiaDinh!$D$32 -> 369054
A6: − Hoa hồng sàn + phí giao dịch | B6: =-B5*(GiaDinh!$B$15+GiaDinh!$C$15) -> -53712.36 | C6: =-C5*(GiaDinh!$B$15+GiaDinh!$C$15) -> -37566.36 | D6: =-D5*(GiaDinh!$B$15+GiaDinh!$C$15) -> -17433 | E6: =-E5*(GiaDinh!$B$15+GiaDinh!$C$15) -> -66578.85 | F6: =-F5*(GiaDinh!$B$15+GiaDinh!$C$15) -> -43179.318
A7: − Thuế sàn khấu trừ | B7: =-B5*GiaDinh!$D$15 -> -3787.41 | C7: =-C5*GiaDinh!$D$15 -> -2648.91 | D7: =-D5*GiaDinh!$D$15 -> -1229.25 | E7: =-E5*GiaDinh!$D$15 -> -4694.6625 | F7: =-F5*GiaDinh!$D$15 -> -3044.6955
A8: − Giá vốn (hàng + in/thêu/khắc + nhãn/hộp) | B8: =-GiaDinh!H28 -> -212000 | C8: =-GiaDinh!H29 -> -156000 | D8: =-GiaDinh!H30 -> -45000 | E8: =-GiaDinh!H31 -> -265000 | F8: =-GiaDinh!$H$32 -> -166850
A9: − Phí cố định sàn/đơn | B9: =-GiaDinh!$F$15 -> -1920 | C9: =-GiaDinh!$F$15 -> -1920 | D9: =-GiaDinh!$F$15 -> -1920 | E9: =-GiaDinh!$F$15 -> -1920 | F9: =-GiaDinh!$F$15 -> -1920
A10: − Ship shop chịu | B10: =-GiaDinh!$B$18 -> -16000 | C10: =-GiaDinh!$B$18 -> -16000 | D10: =-GiaDinh!$B$18 -> -16000 | E10: =-GiaDinh!$B$18 -> -16000 | F10: =-GiaDinh!$B$18 -> -16000
A11: − Bao bì | B11: =-GiaDinh!$B$19 -> -5000 | C11: =-GiaDinh!$B$19 -> -5000 | D11: =-GiaDinh!$B$19 -> -5000 | E11: =-GiaDinh!$B$19 -> -5000 | F11: =-GiaDinh!$B$19 -> -5000
A12: − Dự phòng hoàn hàng | B12: =-GiaDinh!$B$20*GiaDinh!$B$21 -> -4000 | C12: =-GiaDinh!$B$20*GiaDinh!$B$21 -> -4000 | D12: =-GiaDinh!$B$20*GiaDinh!$B$21 -> -4000 | E12: =-GiaDinh!$B$20*GiaDinh!$B$21 -> -4000 | F12: =-GiaDinh!$B$20*GiaDinh!$B$21 -> -4000
A13: − Quảng cáo + affiliate (CAC) | B13: =-GiaDinh!$B$22 -> -30000 | C13: =-GiaDinh!$B$22 -> -30000 | D13: =-GiaDinh!$B$22 -> -30000 | E13: =-GiaDinh!$B$22 -> -30000 | F13: =-GiaDinh!$B$22 -> -30000
A14: LỢI NHUẬN RÒNG / ĐƠN (tổng các dòng trên) | B14: =SUM(B5:B13) -> 132660.23 | C14: =SUM(C5:C13) -> 67944.73 | D14: =SUM(D5:D13) -> 28417.75 | E14: =SUM(E5:E13) -> 175856.49 | F14: =SUM(F5:F13) -> 99059.986
A15: Biên lợi nhuận ròng | B15: =IF(B5=0,0,B14/B5) -> 0.28896974 | C15: =IF(C5=0,0,C14/C5) -> 0.21161309 | D15: =IF(D5=0,0,D14/D5) -> 0.19072315 | E15: =IF(E5=0,0,E14/E5) -> 0.30903521 | F15: =IF(F5=0,0,F14/F5) -> 0.26841597
A16: Lãi gộp / đơn (giá bán − giá vốn) | B16: =B5+B8 -> 247080 | C16: =C5+C8 -> 165080 | D16: =D5+D8 -> 104000 | E16: =E5+E8 -> 304050 | F16: =F5+F8 -> 202204
A17: Số đơn cần để đạt mục tiêu (chưa gồm chi phí cố định) | B17: =IF(B14<=0,"không khả thi",GiaDinh!$B$5/B14) -> 226.14163 | C17: =IF(C14<=0,"không khả thi",GiaDinh!$B$5/C14) -> 441.53535 | D17: =IF(D14<=0,"không khả thi",GiaDinh!$B$5/D14) -> 1055.6782 | E17: =IF(E14<=0,"không khả thi",GiaDinh!$B$5/E14) -> 170.59365 | F17: =IF(F14<=0,"không khả thi",GiaDinh!$B$5/F14) -> 302.8468
A18: Đơn/ngày cần trong 60 ngày | B18: =IF(B14<=0,"-",GiaDinh!$B$5/B14/GiaDinh!$B$8) -> 3.7690271 | C18: =IF(C14<=0,"-",GiaDinh!$B$5/C14/GiaDinh!$B$8) -> 7.3589225 | D18: =IF(D14<=0,"-",GiaDinh!$B$5/D14/GiaDinh!$B$8) -> 17.594637 | E18: =IF(E14<=0,"-",GiaDinh!$B$5/E14/GiaDinh!$B$8) -> 2.8432275 | F18: =IF(F14<=0,"-",GiaDinh!$B$5/F14/GiaDinh!$B$8) -> 5.0474467
A20: Đọc: cột cuối là đơn bình quân. Muốn tăng lợi nhuận/đơn: tăng tỷ trọng kênh trực tiếp (GiaDinh!E), giảm CAC, tăng tỷ trọng Hộp Quà.

Sheet KichBan
A1: KỊCH BẢN 60 NGÀY — lever chính là số đơn/ngày theo kỳ (ô xanh)
A2: Doanh thu và chi phí mỗi kỳ = số đơn × kinh tế đơn vị bình quân. Chi phí cố định nhập theo kỳ.
A4: Kỳ | B4: T1 3–9/11 | C4: T2 10–16/11 | D4: T3 17–23/11 | E4: T4 24–30/11 | F4: T5 1–7/12 | G4: T6 8–14/12 | H4: T7 15–21/12 | I4: T8 22–28/12 | J4: T9 29/12–1/1 | K4: Tổng
A5: Số ngày trong kỳ | B5: 7 | C5: 7 | D5: 7 | E5: 7 | F5: 7 | G5: 7 | H5: 7 | I5: 7 | J5: 4 | K5: =SUM(B5:J5) -> 60
A6: Chi phí cố định/kỳ (mẫu nội dung, mẫu KOC, đạo cụ, công cụ) | B6: 800000 | C6: 500000 | D6: 300000 | E6: 300000 | F6: 400000 | G6: 300000 | H6: 300000 | I6: 200000 | J6: 100000 | K6: =SUM(B6:J6) -> 3200000
A8: KỊCH BẢN: THẬN TRỌNG
A9: Đơn/ngày | B9: 0 | C9: 1 | D9: 2 | E9: 3 | F9: 3 | G9: 4 | H9: 4 | I9: 3 | J9: 3
A10: Số đơn | B10: =B$5*B9 -> 0 | C10: =C$5*C9 -> 7 | D10: =D$5*D9 -> 14 | E10: =E$5*E9 -> 21 | F10: =F$5*F9 -> 21 | G10: =G$5*G9 -> 28 | H10: =H$5*H9 -> 28 | I10: =I$5*I9 -> 21 | J10: =J$5*J9 -> 12 | K10: =SUM(B10:J10) -> 152
A11: Doanh thu (khách trả) | B11: =B10*GiaDinh!$D$32 -> 0 | C11: =C10*GiaDinh!$D$32 -> 2583378 | D11: =D10*GiaDinh!$D$32 -> 5166756 | E11: =E10*GiaDinh!$D$32 -> 7750134 | F11: =F10*GiaDinh!$D$32 -> 7750134 | G11: =G10*GiaDinh!$D$32 -> 10333512 | H11: =H10*GiaDinh!$D$32 -> 10333512 | I11: =I10*GiaDinh!$D$32 -> 7750134 | J11: =J10*GiaDinh!$D$32 -> 4428648 | K11: =SUM(B11:J11) -> 56096208
A12: − Hoa hồng sàn + phí giao dịch | B12: =-B11*(GiaDinh!$B$15+GiaDinh!$C$15) -> 0 | C12: =-C11*(GiaDinh!$B$15+GiaDinh!$C$15) -> -302255.23 | D12: =-D11*(GiaDinh!$B$15+GiaDinh!$C$15) -> -604510.45 | E12: =-E11*(GiaDinh!$B$15+GiaDinh!$C$15) -> -906765.68 | F12: =-F11*(GiaDinh!$B$15+GiaDinh!$C$15) -> -906765.68 | G12: =-G11*(GiaDinh!$B$15+GiaDinh!$C$15) -> -1209020.9 | H12: =-H11*(GiaDinh!$B$15+GiaDinh!$C$15) -> -1209020.9 | I12: =-I11*(GiaDinh!$B$15+GiaDinh!$C$15) -> -906765.68 | J12: =-J11*(GiaDinh!$B$15+GiaDinh!$C$15) -> -518151.82 | K12: =SUM(B12:J12) -> -6563256.3
A13: − Thuế sàn khấu trừ | B13: =-B11*GiaDinh!$D$15 -> 0 | C13: =-C11*GiaDinh!$D$15 -> -21312.869 | D13: =-D11*GiaDinh!$D$15 -> -42625.737 | E13: =-E11*GiaDinh!$D$15 -> -63938.605 | F13: =-F11*GiaDinh!$D$15 -> -63938.605 | G13: =-G11*GiaDinh!$D$15 -> -85251.474 | H13: =-H11*GiaDinh!$D$15 -> -85251.474 | I13: =-I11*GiaDinh!$D$15 -> -63938.605 | J13: =-J11*GiaDinh!$D$15 -> -36536.346 | K13: =SUM(B13:J13) -> -462793.72
A14: − Phí cố định sàn/đơn | B14: =-B10*GiaDinh!$F$15 -> 0 | C14: =-C10*GiaDinh!$F$15 -> -13440 | D14: =-D10*GiaDinh!$F$15 -> -26880 | E14: =-E10*GiaDinh!$F$15 -> -40320 | F14: =-F10*GiaDinh!$F$15 -> -40320 | G14: =-G10*GiaDinh!$F$15 -> -53760 | H14: =-H10*GiaDinh!$F$15 -> -53760 | I14: =-I10*GiaDinh!$F$15 -> -40320 | J14: =-J10*GiaDinh!$F$15 -> -23040 | K14: =SUM(B14:J14) -> -291840
A15: − Giá vốn hàng bán | B15: =-B10*GiaDinh!$H$32 -> 0 | C15: =-C10*GiaDinh!$H$32 -> -1167950 | D15: =-D10*GiaDinh!$H$32 -> -2335900 | E15: =-E10*GiaDinh!$H$32 -> -3503850 | F15: =-F10*GiaDinh!$H$32 -> -3503850 | G15: =-G10*GiaDinh!$H$32 -> -4671800 | H15: =-H10*GiaDinh!$H$32 -> -4671800 | I15: =-I10*GiaDinh!$H$32 -> -3503850 | J15: =-J10*GiaDinh!$H$32 -> -2002200 | K15: =SUM(B15:J15) -> -25361200
A16: − Ship shop chịu + bao bì | B16: =-B10*(GiaDinh!$B$18+GiaDinh!$B$19) -> 0 | C16: =-C10*(GiaDinh!$B$18+GiaDinh!$B$19) -> -147000 | D16: =-D10*(GiaDinh!$B$18+GiaDinh!$B$19) -> -294000 | E16: =-E10*(GiaDinh!$B$18+GiaDinh!$B$19) -> -441000 | F16: =-F10*(GiaDinh!$B$18+GiaDinh!$B$19) -> -441000 | G16: =-G10*(GiaDinh!$B$18+GiaDinh!$B$19) -> -588000 | H16: =-H10*(GiaDinh!$B$18+GiaDinh!$B$19) -> -588000 | I16: =-I10*(GiaDinh!$B$18+GiaDinh!$B$19) -> -441000 | J16: =-J10*(GiaDinh!$B$18+GiaDinh!$B$19) -> -252000 | K16: =SUM(B16:J16) -> -3192000
A17: − Dự phòng hoàn hàng | B17: =-B10*GiaDinh!$B$20*GiaDinh!$B$21 -> 0 | C17: =-C10*GiaDinh!$B$20*GiaDinh!$B$21 -> -28000 | D17: =-D10*GiaDinh!$B$20*GiaDinh!$B$21 -> -56000 | E17: =-E10*GiaDinh!$B$20*GiaDinh!$B$21 -> -84000 | F17: =-F10*GiaDinh!$B$20*GiaDinh!$B$21 -> -84000 | G17: =-G10*GiaDinh!$B$20*GiaDinh!$B$21 -> -112000 | H17: =-H10*GiaDinh!$B$20*GiaDinh!$B$21 -> -112000 | I17: =-I10*GiaDinh!$B$20*GiaDinh!$B$21 -> -84000 | J17: =-J10*GiaDinh!$B$20*GiaDinh!$B$21 -> -48000 | K17: =SUM(B17:J17) -> -608000
A18: − Quảng cáo + affiliate | B18: =-B10*GiaDinh!$B$22 -> 0 | C18: =-C10*GiaDinh!$B$22 -> -210000 | D18: =-D10*GiaDinh!$B$22 -> -420000 | E18: =-E10*GiaDinh!$B$22 -> -630000 | F18: =-F10*GiaDinh!$B$22 -> -630000 | G18: =-G10*GiaDinh!$B$22 -> -840000 | H18: =-H10*GiaDinh!$B$22 -> -840000 | I18: =-I10*GiaDinh!$B$22 -> -630000 | J18: =-J10*GiaDinh!$B$22 -> -360000 | K18: =SUM(B18:J18) -> -4560000
A19: − Chi phí cố định | B19: =-B$6 -> -800000 | C19: =-C$6 -> -500000 | D19: =-D$6 -> -300000 | E19: =-E$6 -> -300000 | F19: =-F$6 -> -400000 | G19: =-G$6 -> -300000 | H19: =-H$6 -> -300000 | I19: =-I$6 -> -200000 | J19: =-J$6 -> -100000 | K19: =SUM(B19:J19) -> -3200000
A20: Lợi nhuận ròng kỳ (tổng các dòng trên) | B20: =SUM(B11:B19) -> -800000 | C20: =SUM(C11:C19) -> 193419.91 | D20: =SUM(D11:D19) -> 1086839.8 | E20: =SUM(E11:E19) -> 1780259.7 | F20: =SUM(F11:F19) -> 1680259.7 | G20: =SUM(G11:G19) -> 2473679.6 | H20: =SUM(H11:H19) -> 2473679.6 | I20: =SUM(I11:I19) -> 1880259.7 | J20: =SUM(J11:J19) -> 1088719.8 | K20: =SUM(B20:J20) -> 11857118
A21: Lũy kế lợi nhuận ròng | B21: =B20 -> -800000 | C21: =C20+B21 -> -606580.09 | D21: =D20+C21 -> 480259.72 | E21: =E20+D21 -> 2260519.4 | F21: =F20+E21 -> 3940779.1 | G21: =G20+F21 -> 6414458.8 | H21: =H20+G21 -> 8888138.4 | I21: =I20+H21 -> 10768398 | J21: =J20+I21 -> 11857118
A22: % mục tiêu đạt được | B22: =B21/GiaDinh!$B$5 -> -0.026666667 | C22: =C21/GiaDinh!$B$5 -> -0.020219336 | D22: =D21/GiaDinh!$B$5 -> 0.016008657 | E22: =E21/GiaDinh!$B$5 -> 0.075350648 | F22: =F21/GiaDinh!$B$5 -> 0.1313593 | G22: =G21/GiaDinh!$B$5 -> 0.21381529 | H22: =H21/GiaDinh!$B$5 -> 0.29627128 | I22: =I21/GiaDinh!$B$5 -> 0.3589466 | J22: =J21/GiaDinh!$B$5 -> 0.39523726
A24: KỊCH BẢN: CƠ SỞ
A25: Đơn/ngày | B25: 1 | C25: 2 | D25: 3 | E25: 5 | F25: 6 | G25: 7 | H25: 8 | I25: 6 | J25: 5
A26: Số đơn | B26: =B$5*B25 -> 7 | C26: =C$5*C25 -> 14 | D26: =D$5*D25 -> 21 | E26: =E$5*E25 -> 35 | F26: =F$5*F25 -> 42 | G26: =G$5*G25 -> 49 | H26: =H$5*H25 -> 56 | I26: =I$5*I25 -> 42 | J26: =J$5*J25 -> 20 | K26: =SUM(B26:J26) -> 286
A27: Doanh thu (khách trả) | B27: =B26*GiaDinh!$D$32 -> 2583378 | C27: =C26*GiaDinh!$D$32 -> 5166756 | D27: =D26*GiaDinh!$D$32 -> 7750134 | E27: =E26*GiaDinh!$D$32 -> 12916890 | F27: =F26*GiaDinh!$D$32 -> 15500268 | G27: =G26*GiaDinh!$D$32 -> 18083646 | H27: =H26*GiaDinh!$D$32 -> 20667024 | I27: =I26*GiaDinh!$D$32 -> 15500268 | J27: =J26*GiaDinh!$D$32 -> 7381080 | K27: =SUM(B27:J27) -> 105549444
A28: − Hoa hồng sàn + phí giao dịch | B28: =-B27*(GiaDinh!$B$15+GiaDinh!$C$15) -> -302255.23 | C28: =-C27*(GiaDinh!$B$15+GiaDinh!$C$15) -> -604510.45 | D28: =-D27*(GiaDinh!$B$15+GiaDinh!$C$15) -> -906765.68 | E28: =-E27*(GiaDinh!$B$15+GiaDinh!$C$15) -> -1511276.1 | F28: =-F27*(GiaDinh!$B$15+GiaDinh!$C$15) -> -1813531.4 | G28: =-G27*(GiaDinh!$B$15+GiaDinh!$C$15) -> -2115786.6 | H28: =-H27*(GiaDinh!$B$15+GiaDinh!$C$15) -> -2418041.8 | I28: =-I27*(GiaDinh!$B$15+GiaDinh!$C$15) -> -1813531.4 | J28: =-J27*(GiaDinh!$B$15+GiaDinh!$C$15) -> -863586.36 | K28: =SUM(B28:J28) -> -12349285
A29: − Thuế sàn khấu trừ | B29: =-B27*GiaDinh!$D$15 -> -21312.869 | C29: =-C27*GiaDinh!$D$15 -> -42625.737 | D29: =-D27*GiaDinh!$D$15 -> -63938.605 | E29: =-E27*GiaDinh!$D$15 -> -106564.34 | F29: =-F27*GiaDinh!$D$15 -> -127877.21 | G29: =-G27*GiaDinh!$D$15 -> -149190.08 | H29: =-H27*GiaDinh!$D$15 -> -170502.95 | I29: =-I27*GiaDinh!$D$15 -> -127877.21 | J29: =-J27*GiaDinh!$D$15 -> -60893.91 | K29: =SUM(B29:J29) -> -870782.91
A30: − Phí cố định sàn/đơn | B30: =-B26*GiaDinh!$F$15 -> -13440 | C30: =-C26*GiaDinh!$F$15 -> -26880 | D30: =-D26*GiaDinh!$F$15 -> -40320 | E30: =-E26*GiaDinh!$F$15 -> -67200 | F30: =-F26*GiaDinh!$F$15 -> -80640 | G30: =-G26*GiaDinh!$F$15 -> -94080 | H30: =-H26*GiaDinh!$F$15 -> -107520 | I30: =-I26*GiaDinh!$F$15 -> -80640 | J30: =-J26*GiaDinh!$F$15 -> -38400 | K30: =SUM(B30:J30) -> -549120
A31: − Giá vốn hàng bán | B31: =-B26*GiaDinh!$H$32 -> -1167950 | C31: =-C26*GiaDinh!$H$32 -> -2335900 | D31: =-D26*GiaDinh!$H$32 -> -3503850 | E31: =-E26*GiaDinh!$H$32 -> -5839750 | F31: =-F26*GiaDinh!$H$32 -> -7007700 | G31: =-G26*GiaDinh!$H$32 -> -8175650 | H31: =-H26*GiaDinh!$H$32 -> -9343600 | I31: =-I26*GiaDinh!$H$32 -> -7007700 | J31: =-J26*GiaDinh!$H$32 -> -3337000 | K31: =SUM(B31:J31) -> -47719100
A32: − Ship shop chịu + bao bì | B32: =-B26*(GiaDinh!$B$18+GiaDinh!$B$19) -> -147000 | C32: =-C26*(GiaDinh!$B$18+GiaDinh!$B$19) -> -294000 | D32: =-D26*(GiaDinh!$B$18+GiaDinh!$B$19) -> -441000 | E32: =-E26*(GiaDinh!$B$18+GiaDinh!$B$19) -> -735000 | F32: =-F26*(GiaDinh!$B$18+GiaDinh!$B$19) -> -882000 | G32: =-G26*(GiaDinh!$B$18+GiaDinh!$B$19) -> -1029000 | H32: =-H26*(GiaDinh!$B$18+GiaDinh!$B$19) -> -1176000 | I32: =-I26*(GiaDinh!$B$18+GiaDinh!$B$19) -> -882000 | J32: =-J26*(GiaDinh!$B$18+GiaDinh!$B$19) -> -420000 | K32: =SUM(B32:J32) -> -6006000
A33: − Dự phòng hoàn hàng | B33: =-B26*GiaDinh!$B$20*GiaDinh!$B$21 -> -28000 | C33: =-C26*GiaDinh!$B$20*GiaDinh!$B$21 -> -56000 | D33: =-D26*GiaDinh!$B$20*GiaDinh!$B$21 -> -84000 | E33: =-E26*GiaDinh!$B$20*GiaDinh!$B$21 -> -140000 | F33: =-F26*GiaDinh!$B$20*GiaDinh!$B$21 -> -168000 | G33: =-G26*GiaDinh!$B$20*GiaDinh!$B$21 -> -196000 | H33: =-H26*GiaDinh!$B$20*GiaDinh!$B$21 -> -224000 | I33: =-I26*GiaDinh!$B$20*GiaDinh!$B$21 -> -168000 | J33: =-J26*GiaDinh!$B$20*GiaDinh!$B$21 -> -80000 | K33: =SUM(B33:J33) -> -1144000
A34: − Quảng cáo + affiliate | B34: =-B26*GiaDinh!$B$22 -> -210000 | C34: =-C26*GiaDinh!$B$22 -> -420000 | D34: =-D26*GiaDinh!$B$22 -> -630000 | E34: =-E26*GiaDinh!$B$22 -> -1050000 | F34: =-F26*GiaDinh!$B$22 -> -1260000 | G34: =-G26*GiaDinh!$B$22 -> -1470000 | H34: =-H26*GiaDinh!$B$22 -> -1680000 | I34: =-I26*GiaDinh!$B$22 -> -1260000 | J34: =-J26*GiaDinh!$B$22 -> -600000 | K34: =SUM(B34:J34) -> -8580000
A35: − Chi phí cố định | B35: =-B$6 -> -800000 | C35: =-C$6 -> -500000 | D35: =-D$6 -> -300000 | E35: =-E$6 -> -300000 | F35: =-F$6 -> -400000 | G35: =-G$6 -> -300000 | H35: =-H$6 -> -300000 | I35: =-I$6 -> -200000 | J35: =-J$6 -> -100000 | K35: =SUM(B35:J35) -> -3200000
A36: Lợi nhuận ròng kỳ (tổng các dòng trên) | B36: =SUM(B27:B35) -> -106580.09 | C36: =SUM(C27:C35) -> 886839.81 | D36: =SUM(D27:D35) -> 1780259.7 | E36: =SUM(E27:E35) -> 3167099.5 | F36: =SUM(F27:F35) -> 3760519.4 | G36: =SUM(G27:G35) -> 4553939.3 | H36: =SUM(H27:H35) -> 5247359.2 | I36: =SUM(I27:I35) -> 3960519.4 | J36: =SUM(J27:J35) -> 1881199.7 | K36: =SUM(B36:J36) -> 25131156
A37: Lũy kế lợi nhuận ròng | B37: =B36 -> -106580.09 | C37: =C36+B37 -> 780259.72 | D37: =D36+C37 -> 2560519.4 | E37: =E36+D37 -> 5727619 | F37: =F36+E37 -> 9488138.4 | G37: =G36+F37 -> 14042078 | H37: =H36+G37 -> 19289437 | I37: =I36+H37 -> 23249956 | J37: =J36+I37 -> 25131156
A38: % mục tiêu đạt được | B38: =B37/GiaDinh!$B$5 -> -0.0035526698 | C38: =C37/GiaDinh!$B$5 -> 0.026008657 | D38: =D37/GiaDinh!$B$5 -> 0.085350648 | E38: =E37/GiaDinh!$B$5 -> 0.19092063 | F38: =F37/GiaDinh!$B$5 -> 0.31627128 | G38: =G37/GiaDinh!$B$5 -> 0.46806926 | H38: =H37/GiaDinh!$B$5 -> 0.64298123 | I38: =I37/GiaDinh!$B$5 -> 0.77499855 | J38: =J37/GiaDinh!$B$5 -> 0.8377052
A40: KỊCH BẢN: TĂNG TỐC
A41: Đơn/ngày | B41: 3 | C41: 5 | D41: 6 | E41: 8 | F41: 10 | G41: 12 | H41: 13 | I41: 9 | J41: 8
A42: Số đơn | B42: =B$5*B41 -> 21 | C42: =C$5*C41 -> 35 | D42: =D$5*D41 -> 42 | E42: =E$5*E41 -> 56 | F42: =F$5*F41 -> 70 | G42: =G$5*G41 -> 84 | H42: =H$5*H41 -> 91 | I42: =I$5*I41 -> 63 | J42: =J$5*J41 -> 32 | K42: =SUM(B42:J42) -> 494
A43: Doanh thu (khách trả) | B43: =B42*GiaDinh!$D$32 -> 7750134 | C43: =C42*GiaDinh!$D$32 -> 12916890 | D43: =D42*GiaDinh!$D$32 -> 15500268 | E43: =E42*GiaDinh!$D$32 -> 20667024 | F43: =F42*GiaDinh!$D$32 -> 25833780 | G43: =G42*GiaDinh!$D$32 -> 31000536 | H43: =H42*GiaDinh!$D$32 -> 33583914 | I43: =I42*GiaDinh!$D$32 -> 23250402 | J43: =J42*GiaDinh!$D$32 -> 11809728 | K43: =SUM(B43:J43) -> 182312676
A44: − Hoa hồng sàn + phí giao dịch | B44: =-B43*(GiaDinh!$B$15+GiaDinh!$C$15) -> -906765.68 | C44: =-C43*(GiaDinh!$B$15+GiaDinh!$C$15) -> -1511276.1 | D44: =-D43*(GiaDinh!$B$15+GiaDinh!$C$15) -> -1813531.4 | E44: =-E43*(GiaDinh!$B$15+GiaDinh!$C$15) -> -2418041.8 | F44: =-F43*(GiaDinh!$B$15+GiaDinh!$C$15) -> -3022552.3 | G44: =-G43*(GiaDinh!$B$15+GiaDinh!$C$15) -> -3627062.7 | H44: =-H43*(GiaDinh!$B$15+GiaDinh!$C$15) -> -3929317.9 | I44: =-I43*(GiaDinh!$B$15+GiaDinh!$C$15) -> -2720297 | J44: =-J43*(GiaDinh!$B$15+GiaDinh!$C$15) -> -1381738.2 | K44: =SUM(B44:J44) -> -21330583
...

Sheet DongTien
A1: DÒNG TIỀN & TỒN KHO — kịch bản Cơ sở, bảo vệ vốn 10 triệu
A2: Tiền về = phần cọc nhận ngay + phần còn lại trễ 1 kỳ. Mua hàng theo đơn (ô xanh). Số dư không được âm ở bất kỳ kỳ nào.
A4: Kỳ | B4: T1 3–9/11 | C4: T2 10–16/11 | D4: T3 17–23/11 | E4: T4 24–30/11 | F4: T5 1–7/12 | G4: T6 8–14/12 | H4: T7 15–21/12 | I4: T8 22–28/12 | J4: T9 29/12–1/1 | K4: Tổng
A5: Số dư đầu kỳ | B5: =GiaDinh!$B$4 -> 10000000 | C5: =B12 -> 6760592.5 | D5: =C12 -> 5982554.9 | E5: =D12 -> 6165887.1 | F5: =E12 -> 6071181.8 | G5: =F12 -> 8238623.8 | H5: =G12 -> 11167436 | I5: =H12 -> 14757618 | J5: =I12 -> 21927392
A6: + Tiền về (doanh thu − phí sàn − thuế − ship): cọc ngay + phần trễ 1 kỳ | B6: =GiaDinh!$B$24*(KichBan!B27+KichBan!B28+KichBan!B29+KichBan!B30-KichBan!B26*GiaDinh!$B$18) -> 533592.48 | C6: =GiaDinh!$B$24*(KichBan!C27+KichBan!C28+KichBan!C29+KichBan!C30-KichBan!C26*GiaDinh!$B$18)+(1-GiaDinh!$B$24)*(KichBan!B27+KichBan!B28+KichBan!B29+KichBan!B30-KichBan!B26*GiaDinh!$B$18) -> 2667962.4 | D6: =GiaDinh!$B$24*(KichBan!D27+KichBan!D28+KichBan!D29+KichBan!D30-KichBan!D26*GiaDinh!$B$18)+(1-GiaDinh!$B$24)*(KichBan!C27+KichBan!C28+KichBan!C29+KichBan!C30-KichBan!C26*GiaDinh!$B$18) -> 4802332.3 | E6: =GiaDinh!$B$24*(KichBan!E27+KichBan!E28+KichBan!E29+KichBan!E30-KichBan!E26*GiaDinh!$B$18)+(1-GiaDinh!$B$24)*(KichBan!D27+KichBan!D28+KichBan!D29+KichBan!D30-KichBan!D26*GiaDinh!$B$18) -> 7470294.7 | F6: =GiaDinh!$B$24*(KichBan!F27+KichBan!F28+KichBan!F29+KichBan!F30-KichBan!F26*GiaDinh!$B$18)+(1-GiaDinh!$B$24)*(KichBan!E27+KichBan!E28+KichBan!E29+KichBan!E30-KichBan!E26*GiaDinh!$B$18) -> 11205442 | G6: =GiaDinh!$B$24*(KichBan!G27+KichBan!G28+KichBan!G29+KichBan!G30-KichBan!G26*GiaDinh!$B$18)+(1-GiaDinh!$B$24)*(KichBan!F27+KichBan!F28+KichBan!F29+KichBan!F30-KichBan!F26*GiaDinh!$B$18) -> 13339812 | H6: =GiaDinh!$B$24*(KichBan!H27+KichBan!H28+KichBan!H29+KichBan!H30-KichBan!H26*GiaDinh!$B$18)+(1-GiaDinh!$B$24)*(KichBan!G27+KichBan!G28+KichBan!G29+KichBan!G30-KichBan!G26*GiaDinh!$B$18) -> 15474182 | I6: =GiaDinh!$B$24*(KichBan!I27+KichBan!I28+KichBan!I29+KichBan!I30-KichBan!I26*GiaDinh!$B$18)+(1-GiaDinh!$B$24)*(KichBan!H27+KichBan!H28+KichBan!H29+KichBan!H30-KichBan!H26*GiaDinh!$B$18) -> 16007774 | J6: =GiaDinh!$B$24*(KichBan!J27+KichBan!J28+KichBan!J29+KichBan!J30-KichBan!J26*GiaDinh!$B$18)+(1-GiaDinh!$B$24)*(KichBan!I27+KichBan!I28+KichBan!I29+KichBan!I30-KichBan!I26*GiaDinh!$B$18) -> 11129215 | K6: =SUM(B6:J6) -> 82630606
A7: − Mua hàng (phôi, in, phụ kiện, hộp) | B7: -2700000 | C7: -2400000 | D7: -3500000 | E7: -5900000 | F7: -7000000 | G7: -8200000 | H7: -9400000 | I7: -7000000 | J7: -3400000 | K7: =SUM(B7:J7) -> -49500000
A8: − Quảng cáo + affiliate | B8: =KichBan!B34 -> -210000 | C8: =KichBan!C34 -> -420000 | D8: =KichBan!D34 -> -630000 | E8: =KichBan!E34 -> -1050000 | F8: =KichBan!F34 -> -1260000 | G8: =KichBan!G34 -> -1470000 | H8: =KichBan!H34 -> -1680000 | I8: =KichBan!I34 -> -1260000 | J8: =KichBan!J34 -> -600000 | K8: =SUM(B8:J8) -> -8580000
A9: − Bao bì + lỗ hoàn hàng | B9: =-KichBan!B26*GiaDinh!$B$19+KichBan!B33 -> -63000 | C9: =-KichBan!C26*GiaDinh!$B$19+KichBan!C33 -> -126000 | D9: =-KichBan!D26*GiaDinh!$B$19+KichBan!D33 -> -189000 | E9: =-KichBan!E26*GiaDinh!$B$19+KichBan!E33 -> -315000 | F9: =-KichBan!F26*GiaDinh!$B$19+KichBan!F33 -> -378000 | G9: =-KichBan!G26*GiaDinh!$B$19+KichBan!G33 -> -441000 | H9: =-KichBan!H26*GiaDinh!$B$19+KichBan!H33 -> -504000 | I9: =-KichBan!I26*GiaDinh!$B$19+KichBan!I33 -> -378000 | J9: =-KichBan!J26*GiaDinh!$B$19+KichBan!J33 -> -180000 | K9: =SUM(B9:J9) -> -2574000
A10: − Chi phí cố định | B10: =KichBan!B35 -> -800000 | C10: =KichBan!C35 -> -500000 | D10: =KichBan!D35 -> -300000 | E10: =KichBan!E35 -> -300000 | F10: =KichBan!F35 -> -400000 | G10: =KichBan!G35 -> -300000 | H10: =KichBan!H35 -> -300000 | I10: =KichBan!I35 -> -200000 | J10: =KichBan!J35 -> -100000 | K10: =SUM(B10:J10) -> -3200000
A11: Dòng tiền ròng kỳ | B11: =SUM(B6:B10) -> -3239407.5 | C11: =SUM(C6:C10) -> -778037.62 | D11: =SUM(D6:D10) -> 183332.29 | E11: =SUM(E6:E10) -> -94705.331 | F11: =SUM(F6:F10) -> 2167442 | G11: =SUM(G6:G10) -> 2928811.9 | H11: =SUM(H6:H10) -> 3590181.8 | I11: =SUM(I6:I10) -> 7169774.3 | J11: =SUM(J6:J10) -> 6849214.5 | K11: =SUM(B11:J11) -> 18776606
A12: Số dư cuối kỳ | B12: =B5+B11 -> 6760592.5 | C12: =C5+C11 -> 5982554.9 | D12: =D5+D11 -> 6165887.1 | E12: =E5+E11 -> 6071181.8 | F12: =F5+F11 -> 8238623.8 | G12: =G5+G11 -> 11167436 | H12: =H5+H11 -> 14757618 | I12: =I5+I11 -> 21927392 | J12: =J5+J11 -> 28776606
A14: TỒN KHO (đơn vị = bộ/đơn bình quân)
A15: Số bộ mua vào (= tiền mua hàng ÷ giá vốn bình quân) | B15: =-B7/GiaDinh!$H$32 -> 16.1822 | C15: =-C7/GiaDinh!$H$32 -> 14.384177 | D15: =-D7/GiaDinh!$H$32 -> 20.976925 | E15: =-E7/GiaDinh!$H$32 -> 35.361103 | F15: =-F7/GiaDinh!$H$32 -> 41.953851 | G15: =-G7/GiaDinh!$H$32 -> 49.145939 | H15: =-H7/GiaDinh!$H$32 -> 56.338028 | I15: =-I7/GiaDinh!$H$32 -> 41.953851 | J15: =-J7/GiaDinh!$H$32 -> 20.377585 | K15: =SUM(B15:J15) -> 296.67366
A16: Số bộ bán ra (đơn) | B16: =KichBan!B26 -> 7 | C16: =KichBan!C26 -> 14 | D16: =KichBan!D26 -> 21 | E16: =KichBan!E26 -> 35 | F16: =KichBan!F26 -> 42 | G16: =KichBan!G26 -> 49 | H16: =KichBan!H26 -> 56 | I16: =KichBan!I26 -> 42 | J16: =KichBan!J26 -> 20 | K16: =SUM(B16:J16) -> 286
A17: Tồn cuối kỳ (bộ) | B17: =B15-B16 -> 9.1821996 | C17: =B17+C15-C16 -> 9.566377 | D17: =C17+D15-D16 -> 9.5433024 | E17: =D17+E15-E16 -> 9.9044052 | F17: =E17+F15-F16 -> 9.8582559 | G17: =F17+G15-G16 -> 10.004195 | H17: =G17+H15-H16 -> 10.342224 | I17: =H17+I15-I16 -> 10.296074 | J17: =I17+J15-J16 -> 10.673659
A18: Giá trị tồn kho (₫) | B18: =B17*GiaDinh!$H$32 -> 1532050 | C18: =C17*GiaDinh!$H$32 -> 1596150 | D18: =D17*GiaDinh!$H$32 -> 1592300 | E18: =E17*GiaDinh!$H$32 -> 1652550 | F18: =F17*GiaDinh!$H$32 -> 1644850 | G18: =G17*GiaDinh!$H$32 -> 1669200 | H18: =H17*GiaDinh!$H$32 -> 1725600 | I18: =I17*GiaDinh!$H$32 -> 1717900 | J18: =J17*GiaDinh!$H$32 -> 1780900
A20: Số dư thấp nhất trong 60 ngày | B20: =MIN(B12:J12) -> 5982554.9 | C20: =IF(B20>=0,"AN TOÀN: không âm vốn","CẢNH BÁO: âm tiền — giảm mua hàng/ads kỳ đó hoặc tăng cọc") -> AN TOÀN: không âm vốn
A21: Tiền mặt cuối kỳ 9 + giá trị tồn kho | B21: =J12+J18 -> 30557506
A22: Tiền chưa về (phần doanh thu kỳ cuối chưa đối soát) | B22: =(1-GiaDinh!$B$24)*(KichBan!J27+KichBan!J28+KichBan!J29+KichBan!J30-KichBan!J26*GiaDinh!$B$18) -> 4573649.8
A23: Đối soát: (B21 + B22 − vốn) phải bằng LN ròng Cơ sở | B23: =B21+B22-GiaDinh!$B$4 -> 25131156 | C23: =KichBan!K36 -> 25131156 | D23: =IF(ABS(B23-C23)<1,"KHỚP","LỆCH") -> KHỚP
A24: Tồn kho cuối cùng (bộ) — nên ≈ 0 vì làm theo đơn | B24: =J17 -> 10.673659
A25: Tổng tiền mua hàng | tổng giá vốn bán ra | B25: =-K7 -> 49500000 | C25: =-KichBan!K31 -> 47719100

Sheet VonBanDau
A1: PHÂN BỔ VỐN BAN ĐẦU 10.000.000 ₫
A3: Khoản | B3: Số tiền (₫) | C3: Nguyên tắc giải ngân
A4: Mẫu + phôi dự trữ đợt 1 (6 áo nỉ, 6 áo thun, 20 cặp vòng, 10 nhẫn/móc khóa) | B4: 2500000 | C4: Mua ngày 3–5/11 ngay khi lương về; phôi còn lại mua theo đơn
A5: Thử in/thêu/khắc mẫu, tem nhãn | B5: 500000 | C5: Báo giá xin trước 3/11; thử mẫu 3–6/11
A6: Bao bì thương hiệu 100 bộ (túi kraft, sticker, thiệp, hộp) | B6: 700000 | C6: HOSO/Azoka/In Thủ Đô, giao 1–3 ngày
A7: Mẫu tặng KOC + đạo cụ quay (5–8 cặp) | B7: 1000000 | C7: Đổi video, không trả tiền mặt; chấm KOC qua tab trưng bày
A8: Quảng cáo thử nghiệm TikTok | B8: 1500000 | C8: 100k/ngày cho 1 video đã có view tự nhiên tốt; trần 10% doanh thu
A9: Vốn lưu động mua phôi theo đơn trước khi tiền về | B9: 3000000 | C9: Chỉ dùng khi đã có đơn/cọc tương ứng
A10: Dự phòng (hoàn hàng, ship, sự cố) | B10: 800000 | C10: Không chạm trong 4 tuần đầu
A11: Tổng phân bổ | B11: =SUM(B4:B10) -> 10000000
A12: Vốn ban đầu | B12: =GiaDinh!$B$4 -> 10000000
A13: Chênh lệch (phải ≥ 0) | B13: =B12-B11 -> 0 | C13: =IF(B13>=0,"OK","VƯỢT VỐN") -> OK
A15: Quy tắc: không chi quá 40% vốn trước khi có 20 đơn đầu tiên; đợt mua phôi sau đều đối ứng bằng đơn/cọc đã có.

Sheet KPI
A1: KPI & ĐỘ NHẠY — cần bao nhiêu đơn/ngày để ra 30 triệu?
A3: Lợi nhuận ròng/đơn bình quân (DonVi) | B3: =DonVi!$F$14 -> 99059.986
A4: Tổng chi phí cố định 60 ngày (KichBan) | B4: =KichBan!$K$6 -> 3200000
A5: Số đơn cần (gồm bù chi phí cố định) | B5: =IF(B3<=0,"-",(GiaDinh!$B$5+B4)/B3) -> 335.15046
A6: Đơn/ngày cần nếu bán đều 60 ngày | B6: =IF(B3<=0,"-",B5/GiaDinh!$B$8) -> 5.585841
A7: Đơn/ngày cần nếu tuần cuối (29/12–1/1) chỉ bằng nửa (56 ngày hiệu dụng) | B7: =IF(B3<=0,"-",B5/(GiaDinh!$B$8-4)) -> 5.9848296
A8: Doanh thu cần (₫) | B8: =IF(B3<=0,"-",B5*GiaDinh!$D$32) -> 1.2368862e+08
A10: ĐỘ NHẠY: LN ròng 60 ngày theo LN/đơn (hàng) × đơn/ngày bình quân (cột), đã trừ chi phí cố định
A11: LN/đơn ↓ | đơn/ngày → | B11: 2 | C11: 3 | D11: 4 | E11: 5 | F11: 6 | G11: 7 | H11: 8 | I11: 10
A12: 60000 | B12: =$A12*B$11*GiaDinh!$B$8-$B$4 -> 4000000 | C12: =$A12*C$11*GiaDinh!$B$8-$B$4 -> 7600000 | D12: =$A12*D$11*GiaDinh!$B$8-$B$4 -> 11200000 | E12: =$A12*E$11*GiaDinh!$B$8-$B$4 -> 14800000 | F12: =$A12*F$11*GiaDinh!$B$8-$B$4 -> 18400000 | G12: =$A12*G$11*GiaDinh!$B$8-$B$4 -> 22000000 | H12: =$A12*H$11*GiaDinh!$B$8-$B$4 -> 25600000 | I12: =$A12*I$11*GiaDinh!$B$8-$B$4 -> 32800000
A13: 80000 | B13: =$A13*B$11*GiaDinh!$B$8-$B$4 -> 6400000 | C13: =$A13*C$11*GiaDinh!$B$8-$B$4 -> 11200000 | D13: =$A13*D$11*GiaDinh!$B$8-$B$4 -> 16000000 | E13: =$A13*E$11*GiaDinh!$B$8-$B$4 -> 20800000 | F13: =$A13*F$11*GiaDinh!$B$8-$B$4 -> 25600000 | G13: =$A13*G$11*GiaDinh!$B$8-$B$4 -> 30400000 | H13: =$A13*H$11*GiaDinh!$B$8-$B$4 -> 35200000 | I13: =$A13*I$11*GiaDinh!$B$8-$B$4 -> 44800000
A14: 100000 | B14: =$A14*B$11*GiaDinh!$B$8-$B$4 -> 8800000 | C14: =$A14*C$11*GiaDinh!$B$8-$B$4 -> 14800000 | D14: =$A14*D$11*GiaDinh!$B$8-$B$4 -> 20800000 | E14: =$A14*E$11*GiaDinh!$B$8-$B$4 -> 26800000 | F14: =$A14*F$11*GiaDinh!$B$8-$B$4 -> 32800000 | G14: =$A14*G$11*GiaDinh!$B$8-$B$4 -> 38800000 | H14: =$A14*H$11*GiaDinh!$B$8-$B$4 -> 44800000 | I14: =$A14*I$11*GiaDinh!$B$8-$B$4 -> 56800000
A15: 120000 | B15: =$A15*B$11*GiaDinh!$B$8-$B$4 -> 11200000 | C15: =$A15*C$11*GiaDinh!$B$8-$B$4 -> 18400000 | D15: =$A15*D$11*GiaDinh!$B$8-$B$4 -> 25600000 | E15: =$A15*E$11*GiaDinh!$B$8-$B$4 -> 32800000 | F15: =$A15*F$11*GiaDinh!$B$8-$B$4 -> 40000000 | G15: =$A15*G$11*GiaDinh!$B$8-$B$4 -> 47200000 | H15: =$A15*H$11*GiaDinh!$B$8-$B$4 -> 54400000 | I15: =$A15*I$11*GiaDinh!$B$8-$B$4 -> 68800000
A16: 140000 | B16: =$A16*B$11*GiaDinh!$B$8-$B$4 -> 13600000 | C16: =$A16*C$11*GiaDinh!$B$8-$B$4 -> 22000000 | D16: =$A16*D$11*GiaDinh!$B$8-$B$4 -> 30400000 | E16: =$A16*E$11*GiaDinh!$B$8-$B$4 -> 38800000 | F16: =$A16*F$11*GiaDinh!$B$8-$B$4 -> 47200000 | G16: =$A16*G$11*GiaDinh!$B$8-$B$4 -> 55600000 | H16: =$A16*H$11*GiaDinh!$B$8-$B$4 -> 64000000 | I16: =$A16*I$11*GiaDinh!$B$8-$B$4 -> 80800000
A17: 160000 | B17: =$A17*B$11*GiaDinh!$B$8-$B$4 -> 16000000 | C17: =$A17*C$11*GiaDinh!$B$8-$B$4 -> 25600000 | D17: =$A17*D$11*GiaDinh!$B$8-$B$4 -> 35200000 | E17: =$A17*E$11*GiaDinh!$B$8-$B$4 -> 44800000 | F17: =$A17*F$11*GiaDinh!$B$8-$B$4 -> 54400000 | G17: =$A17*G$11*GiaDinh!$B$8-$B$4 -> 64000000 | H17: =$A17*H$11*GiaDinh!$B$8-$B$4 -> 73600000 | I17: =$A17*I$11*GiaDinh!$B$8-$B$4 -> 92800000
A18: 180000 | B18: =$A18*B$11*GiaDinh!$B$8-$B$4 -> 18400000 | C18: =$A18*C$11*GiaDinh!$B$8-$B$4 -> 29200000 | D18: =$A18*D$11*GiaDinh!$B$8-$B$4 -> 40000000 | E18: =$A18*E$11*GiaDinh!$B$8-$B$4 -> 50800000 | F18: =$A18*F$11*GiaDinh!$B$8-$B$4 -> 61600000 | G18: =$A18*G$11*GiaDinh!$B$8-$B$4 -> 72400000 | H18: =$A18*H$11*GiaDinh!$B$8-$B$4 -> 83200000 | I18: =$A18*I$11*GiaDinh!$B$8-$B$4 -> 104800000
A19: 200000 | B19: =$A19*B$11*GiaDinh!$B$8-$B$4 -> 20800000 | C19: =$A19*C$11*GiaDinh!$B$8-$B$4 -> 32800000 | D19: =$A19*D$11*GiaDinh!$B$8-$B$4 -> 44800000 | E19: =$A19*E$11*GiaDinh!$B$8-$B$4 -> 56800000 | F19: =$A19*F$11*GiaDinh!$B$8-$B$4 -> 68800000 | G19: =$A19*G$11*GiaDinh!$B$8-$B$4 -> 80800000 | H19: =$A19*H$11*GiaDinh!$B$8-$B$4 -> 92800000 | I19: =$A19*I$11*GiaDinh!$B$8-$B$4 -> 116800000
A21: Ô ≥ 30.000.000 là tổ hợp đạt KPI. Đọc hàng gần nhất với LN/đơn thực tế của bạn trong DonVi.
A23: 4 ĐÒN BẨY ĐỂ TĂNG LN/ĐƠN (sửa ở GiaDinh rồi xem lại B3):
A24: 1. Tỷ trọng kênh trực tiếp 45% → 60%: bớt ~5 điểm % phí sàn
A25: 2. TikTok 0% phí giao dịch 60 ngày (nếu đủ điều kiện shop mới): +6% trên đơn TikTok
A26: 3. CAC 30k → 20k nhờ video tự nhiên + affiliate thay vì ads
A27: 4. Tỷ trọng Hộp Quà 20% → 30%: AOV tăng, phí cố định/đơn không đổi
